Workbook

Sheet Home
D3: Category Selection
C8: BHT TRACKER - FEBRUARY 2026 DAT ROLLING ANALYSIS
D9: Base
C10: {=IFERROR(HYPERLINK( "#'" & _xlfn.IFS( BackEnd!$F$5="Noodles", IF(BackEnd!$E$2=2, "N_%", "N_Count"), BackEnd!$F$5="Toothpaste", IF(BackEnd!$E$2=2, "TP_%", "TP_Count"), BackEnd!$F$5="Breakfast Cereal", IF(BackEnd!$E$2=2, "BC_%", "BC_Count"), BackEnd!$F$5="Bleach", IF(BackEnd!$E$2=2, "BL_%", "BL_Count"), BackEnd!$F$5="Edible Oil", IF(BackEnd!$E$2=2, "EO_%", "EO_Count"), BackEnd!$F$5="Snacks", IF(BackEnd!$E$2=2, "SK_%", "SK_Count"), BackEnd!$F$5="Condiment Mixes", IF(BackEnd!$E$2=2, "CM_%", "CM_Count"), BackEnd!$F$5="Wet Hair", IF(BackEnd!$E$2=2, "WH_%", "WH_Count"), BackEnd!$F$5="Dry Hair", IF(BackEnd!$E$2=2, "DH_%", "DH_Count"), BackEnd!$F$5="Toilet Cleaner", IF(BackEnd!$E$2=2, "TC_%", "TC_Count") ) & "'!A" & MATCH( BackEnd!B6, INDIRECT("'" & _xlfn.IFS( BackEnd!$F$5="Noodles", IF(BackEnd!$E$2=2, "N_%", "N_Count"), BackEnd!$F$5="Toothpaste", IF(BackEnd!$E$2=2, "TP_%", "TP_Count"), BackEnd!$F$5="Breakfast Cereal", IF(BackEnd!$E$2=2, "BC_%", "BC_Count"), BackEnd!$F$5="Bleach", IF(BackEnd!$E$2=2, "BL_%", "BL_Count"), BackEnd!$F$5="Edible Oil", IF(BackEnd!$E$2=2, "EO_%", "EO_Count"), BackEnd!$F$5="Snacks", IF(BackEnd!$E$2=2, "SK_%", "SK_Count"), BackEnd!$F$5="Condiment Mixes", IF(BackEnd!$E$2=2, "CM_%", "CM_Count"), BackEnd!$F$5="Wet Hair", IF(BackEnd!$E$2=2, "WH_%", "WH_Count"), BackEnd!$F$5="Dry Hair", IF(BackEnd!$E$2=2, "DH_%", "DH_Count"), BackEnd!$F$5="Toilet Cleaner", IF(BackEnd!$E$2=2, "TC_%", "TC_Count") ) & "'!A:A" ), 0 ), BackEnd!B6 ),"")} | D10: =IF(BackEnd!C6="","",BackEnd!C6) -> #REF!
C11: {=IFERROR(HYPERLINK( "#'" & _xlfn.IFS( BackEnd!$F$5="Noodles", IF(BackEnd!$E$2=2, "N_%", "N_Count"), BackEnd!$F$5="Toothpaste", IF(BackEnd!$E$2=2, "TP_%", "TP_Count"), BackEnd!$F$5="Breakfast Cereal", IF(BackEnd!$E$2=2, "BC_%", "BC_Count"), BackEnd!$F$5="Bleach", IF(BackEnd!$E$2=2, "BL_%", "BL_Count"), BackEnd!$F$5="Edible Oil", IF(BackEnd!$E$2=2, "EO_%", "EO_Count"), BackEnd!$F$5="Snacks", IF(BackEnd!$E$2=2, "SK_%", "SK_Count"), BackEnd!$F$5="Condiment Mixes", IF(BackEnd!$E$2=2, "CM_%", "CM_Count"), BackEnd!$F$5="Wet Hair", IF(BackEnd!$E$2=2, "WH_%", "WH_Count"), BackEnd!$F$5="Dry Hair", IF(BackEnd!$E$2=2, "DH_%", "DH_Count"), BackEnd!$F$5="Toilet Cleaner", IF(BackEnd!$E$2=2, "TC_%", "TC_Count") ) & "'!A" & MATCH( BackEnd!B7, INDIRECT("'" & _xlfn.IFS( BackEnd!$F$5="Noodles", IF(BackEnd!$E$2=2, "N_%", "N_Count"), BackEnd!$F$5="Toothpaste", IF(BackEnd!$E$2=2, "TP_%", "TP_Count"), BackEnd!$F$5="Breakfast Cereal", IF(BackEnd!$E$2=2, "BC_%", "BC_Count"), BackEnd!$F$5="Bleach", IF(BackEnd!$E$2=2, "BL_%", "BL_Count"), BackEnd!$F$5="Edible Oil", IF(BackEnd!$E$2=2, "EO_%", "EO_Count"), BackEnd!$F$5="Snacks", IF(BackEnd!$E$2=2, "SK_%", "SK_Count"), BackEnd!$F$5="Condiment Mixes", IF(BackEnd!$E$2=2, "CM_%", "CM_Count"), BackEnd!$F$5="Wet Hair", IF(BackEnd!$E$2=2, "WH_%", "WH_Count"), BackEnd!$F$5="Dry Hair", IF(BackEnd!$E$2=2, "DH_%", "DH_Count"), BackEnd!$F$5="Toilet Cleaner", IF(BackEnd!$E$2=2, "TC_%", "TC_Count") ) & "'!A:A" ), 0 ), BackEnd!B7 ),"")} | D11: =IF(BackEnd!C7="","",BackEnd!C7) -> #REF!
C12: {=IFERROR(HYPERLINK( "#'" & _xlfn.IFS( BackEnd!$F$5="Noodles", IF(BackEnd!$E$2=2, "N_%", "N_Count"), BackEnd!$F$5="Toothpaste", IF(BackEnd!$E$2=2, "TP_%", "TP_Count"), BackEnd!$F$5="Breakfast Cereal", IF(BackEnd!$E$2=2, "BC_%", "BC_Count"), BackEnd!$F$5="Bleach", IF(BackEnd!$E$2=2, "BL_%", "BL_Count"), BackEnd!$F$5="Edible Oil", IF(BackEnd!$E$2=2, "EO_%", "EO_Count"), BackEnd!$F$5="Snacks", IF(BackEnd!$E$2=2, "SK_%", "SK_Count"), BackEnd!$F$5="Condiment Mixes", IF(BackEnd!$E$2=2, "CM_%", "CM_Count"), BackEnd!$F$5="Wet Hair", IF(BackEnd!$E$2=2, "WH_%", "WH_Count"), BackEnd!$F$5="Dry Hair", IF(BackEnd!$E$2=2, "DH_%", "DH_Count"), BackEnd!$F$5="Toilet Cleaner", IF(BackEnd!$E$2=2, "TC_%", "TC_Count") ) & "'!A" & MATCH( BackEnd!B8, INDIRECT("'" & _xlfn.IFS( BackEnd!$F$5="Noodles", IF(BackEnd!$E$2=2, "N_%", "N_Count"), BackEnd!$F$5="Toothpaste", IF(BackEnd!$E$2=2, "TP_%", "TP_Count"), BackEnd!$F$5="Breakfast Cereal", IF(BackEnd!$E$2=2, "BC_%", "BC_Count"), BackEnd!$F$5="Bleach", IF(BackEnd!$E$2=2, "BL_%", "BL_Count"), BackEnd!$F$5="Edible Oil", IF(BackEnd!$E$2=2, "EO_%", "EO_Count"), BackEnd!$F$5="Snacks", IF(BackEnd!$E$2=2, "SK_%", "SK_Count"), BackEnd!$F$5="Condiment Mixes", IF(BackEnd!$E$2=2, "CM_%", "CM_Count"), BackEnd!$F$5="Wet Hair", IF(BackEnd!$E$2=2, "WH_%", "WH_Count"), BackEnd!$F$5="Dry Hair", IF(BackEnd!$E$2=2, "DH_%", "DH_Count"), BackEnd!$F$5="Toilet Cleaner", IF(BackEnd!$E$2=2, "TC_%", "TC_Count") ) & "'!A:A" ), 0 ), BackEnd!B8 ),"")} | D12: =IF(BackEnd!C8="","",BackEnd!C8) -> #REF!
C13: {=IFERROR(HYPERLINK( "#'" & _xlfn.IFS( BackEnd!$F$5="Noodles", IF(BackEnd!$E$2=2, "N_%", "N_Count"), BackEnd!$F$5="Toothpaste", IF(BackEnd!$E$2=2, "TP_%", "TP_Count"), BackEnd!$F$5="Breakfast Cereal", IF(BackEnd!$E$2=2, "BC_%", "BC_Count"), BackEnd!$F$5="Bleach", IF(BackEnd!$E$2=2, "BL_%", "BL_Count"), BackEnd!$F$5="Edible Oil", IF(BackEnd!$E$2=2, "EO_%", "EO_Count"), BackEnd!$F$5="Snacks", IF(BackEnd!$E$2=2, "SK_%", "SK_Count"), BackEnd!$F$5="Condiment Mixes", IF(BackEnd!$E$2=2, "CM_%", "CM_Count"), BackEnd!$F$5="Wet Hair", IF(BackEnd!$E$2=2, "WH_%", "WH_Count"), BackEnd!$F$5="Dry Hair", IF(BackEnd!$E$2=2, "DH_%", "DH_Count"), BackEnd!$F$5="Toilet Cleaner", IF(BackEnd!$E$2=2, "TC_%", "TC_Count") ) & "'!A" & MATCH( BackEnd!B9, INDIRECT("'" & _xlfn.IFS( BackEnd!$F$5="Noodles", IF(BackEnd!$E$2=2, "N_%", "N_Count"), BackEnd!$F$5="Toothpaste", IF(BackEnd!$E$2=2, "TP_%", "TP_Count"), BackEnd!$F$5="Breakfast Cereal", IF(BackEnd!$E$2=2, "BC_%", "BC_Count"), BackEnd!$F$5="Bleach", IF(BackEnd!$E$2=2, "BL_%", "BL_Count"), BackEnd!$F$5="Edible Oil", IF(BackEnd!$E$2=2, "EO_%", "EO_Count"), BackEnd!$F$5="Snacks", IF(BackEnd!$E$2=2, "SK_%", "SK_Count"), BackEnd!$F$5="Condiment Mixes", IF(BackEnd!$E$2=2, "CM_%", "CM_Count"), BackEnd!$F$5="Wet Hair", IF(BackEnd!$E$2=2, "WH_%", "WH_Count"), BackEnd!$F$5="Dry Hair", IF(BackEnd!$E$2=2, "DH_%", "DH_Count"), BackEnd!$F$5="Toilet Cleaner", IF(BackEnd!$E$2=2, "TC_%", "TC_Count") ) & "'!A:A" ), 0 ), BackEnd!B9 ),"")} | D13: =IF(BackEnd!C9="","",BackEnd!C9) -> #REF!
C14: {=IFERROR(HYPERLINK( "#'" & _xlfn.IFS( BackEnd!$F$5="Noodles", IF(BackEnd!$E$2=2, "N_%", "N_Count"), BackEnd!$F$5="Toothpaste", IF(BackEnd!$E$2=2, "TP_%", "TP_Count"), BackEnd!$F$5="Breakfast Cereal", IF(BackEnd!$E$2=2, "BC_%", "BC_Count"), BackEnd!$F$5="Bleach", IF(BackEnd!$E$2=2, "BL_%", "BL_Count"), BackEnd!$F$5="Edible Oil", IF(BackEnd!$E$2=2, "EO_%", "EO_Count"), BackEnd!$F$5="Snacks", IF(BackEnd!$E$2=2, "SK_%", "SK_Count"), BackEnd!$F$5="Condiment Mixes", IF(BackEnd!$E$2=2, "CM_%", "CM_Count"), BackEnd!$F$5="Wet Hair", IF(BackEnd!$E$2=2, "WH_%", "WH_Count"), BackEnd!$F$5="Dry Hair", IF(BackEnd!$E$2=2, "DH_%", "DH_Count"), BackEnd!$F$5="Toilet Cleaner", IF(BackEnd!$E$2=2, "TC_%", "TC_Count") ) & "'!A" & MATCH( BackEnd!B10, INDIRECT("'" & _xlfn.IFS( BackEnd!$F$5="Noodles", IF(BackEnd!$E$2=2, "N_%", "N_Count"), BackEnd!$F$5="Toothpaste", IF(BackEnd!$E$2=2, "TP_%", "TP_Count"), BackEnd!$F$5="Breakfast Cereal", IF(BackEnd!$E$2=2, "BC_%", "BC_Count"), BackEnd!$F$5="Bleach", IF(BackEnd!$E$2=2, "BL_%", "BL_Count"), BackEnd!$F$5="Edible Oil", IF(BackEnd!$E$2=2, "EO_%", "EO_Count"), BackEnd!$F$5="Snacks", IF(BackEnd!$E$2=2, "SK_%", "SK_Count"), BackEnd!$F$5="Condiment Mixes", IF(BackEnd!$E$2=2, "CM_%", "CM_Count"), BackEnd!$F$5="Wet Hair", IF(BackEnd!$E$2=2, "WH_%", "WH_Count"), BackEnd!$F$5="Dry Hair", IF(BackEnd!$E$2=2, "DH_%", "DH_Count"), BackEnd!$F$5="Toilet Cleaner", IF(BackEnd!$E$2=2, "TC_%", "TC_Count") ) & "'!A:A" ), 0 ), BackEnd!B10 ),"")} | D14: =IF(BackEnd!C10="","",BackEnd!C10) -> #REF!
C15: {=IFERROR(HYPERLINK( "#'" & _xlfn.IFS( BackEnd!$F$5="Noodles", IF(BackEnd!$E$2=2, "N_%", "N_Count"), BackEnd!$F$5="Toothpaste", IF(BackEnd!$E$2=2, "TP_%", "TP_Count"), BackEnd!$F$5="Breakfast Cereal", IF(BackEnd!$E$2=2, "BC_%", "BC_Count"), BackEnd!$F$5="Bleach", IF(BackEnd!$E$2=2, "BL_%", "BL_Count"), BackEnd!$F$5="Edible Oil", IF(BackEnd!$E$2=2, "EO_%", "EO_Count"), BackEnd!$F$5="Snacks", IF(BackEnd!$E$2=2, "SK_%", "SK_Count"), BackEnd!$F$5="Condiment Mixes", IF(BackEnd!$E$2=2, "CM_%", "CM_Count"), BackEnd!$F$5="Wet Hair", IF(BackEnd!$E$2=2, "WH_%", "WH_Count"), BackEnd!$F$5="Dry Hair", IF(BackEnd!$E$2=2, "DH_%", "DH_Count"), BackEnd!$F$5="Toilet Cleaner", IF(BackEnd!$E$2=2, "TC_%", "TC_Count") ) & "'!A" & MATCH( BackEnd!B11, INDIRECT("'" & _xlfn.IFS( BackEnd!$F$5="Noodles", IF(BackEnd!$E$2=2, "N_%", "N_Count"), BackEnd!$F$5="Toothpaste", IF(BackEnd!$E$2=2, "TP_%", "TP_Count"), BackEnd!$F$5="Breakfast Cereal", IF(BackEnd!$E$2=2, "BC_%", "BC_Count"), BackEnd!$F$5="Bleach", IF(BackEnd!$E$2=2, "BL_%", "BL_Count"), BackEnd!$F$5="Edible Oil", IF(BackEnd!$E$2=2, "EO_%", "EO_Count"), BackEnd!$F$5="Snacks", IF(BackEnd!$E$2=2, "SK_%", "SK_Count"), BackEnd!$F$5="Condiment Mixes", IF(BackEnd!$E$2=2, "CM_%", "CM_Count"), BackEnd!$F$5="Wet Hair", IF(BackEnd!$E$2=2, "WH_%", "WH_Count"), BackEnd!$F$5="Dry Hair", IF(BackEnd!$E$2=2, "DH_%", "DH_Count"), BackEnd!$F$5="Toilet Cleaner", IF(BackEnd!$E$2=2, "TC_%", "TC_Count") ) & "'!A:A" ), 0 ), BackEnd!B11 ),"")} | D15: =IF(BackEnd!C11="","",BackEnd!C11) -> #REF!
C16: {=IFERROR(HYPERLINK( "#'" & _xlfn.IFS( BackEnd!$F$5="Noodles", IF(BackEnd!$E$2=2, "N_%", "N_Count"), BackEnd!$F$5="Toothpaste", IF(BackEnd!$E$2=2, "TP_%", "TP_Count"), BackEnd!$F$5="Breakfast Cereal", IF(BackEnd!$E$2=2, "BC_%", "BC_Count"), BackEnd!$F$5="Bleach", IF(BackEnd!$E$2=2, "BL_%", "BL_Count"), BackEnd!$F$5="Edible Oil", IF(BackEnd!$E$2=2, "EO_%", "EO_Count"), BackEnd!$F$5="Snacks", IF(BackEnd!$E$2=2, "SK_%", "SK_Count"), BackEnd!$F$5="Condiment Mixes", IF(BackEnd!$E$2=2, "CM_%", "CM_Count"), BackEnd!$F$5="Wet Hair", IF(BackEnd!$E$2=2, "WH_%", "WH_Count"), BackEnd!$F$5="Dry Hair", IF(BackEnd!$E$2=2, "DH_%", "DH_Count"), BackEnd!$F$5="Toilet Cleaner", IF(BackEnd!$E$2=2, "TC_%", "TC_Count") ) & "'!A" & MATCH( BackEnd!B12, INDIRECT("'" & _xlfn.IFS( BackEnd!$F$5="Noodles", IF(BackEnd!$E$2=2, "N_%", "N_Count"), BackEnd!$F$5="Toothpaste", IF(BackEnd!$E$2=2, "TP_%", "TP_Count"), BackEnd!$F$5="Breakfast Cereal", IF(BackEnd!$E$2=2, "BC_%", "BC_Count"), BackEnd!$F$5="Bleach", IF(BackEnd!$E$2=2, "BL_%", "BL_Count"), BackEnd!$F$5="Edible Oil", IF(BackEnd!$E$2=2, "EO_%", "EO_Count"), BackEnd!$F$5="Snacks", IF(BackEnd!$E$2=2, "SK_%", "SK_Count"), BackEnd!$F$5="Condiment Mixes", IF(BackEnd!$E$2=2, "CM_%", "CM_Count"), BackEnd!$F$5="Wet Hair", IF(BackEnd!$E$2=2, "WH_%", "WH_Count"), BackEnd!$F$5="Dry Hair", IF(BackEnd!$E$2=2, "DH_%", "DH_Count"), BackEnd!$F$5="Toilet Cleaner", IF(BackEnd!$E$2=2, "TC_%", "TC_Count") ) & "'!A:A" ), 0 ), BackEnd!B12 ),"")} | D16: =IF(BackEnd!C12="","",BackEnd!C12) -> #REF!
C17: {=IFERROR(HYPERLINK( "#'" & _xlfn.IFS( BackEnd!$F$5="Noodles", IF(BackEnd!$E$2=2, "N_%", "N_Count"), BackEnd!$F$5="Toothpaste", IF(BackEnd!$E$2=2, "TP_%", "TP_Count"), BackEnd!$F$5="Breakfast Cereal", IF(BackEnd!$E$2=2, "BC_%", "BC_Count"), BackEnd!$F$5="Bleach", IF(BackEnd!$E$2=2, "BL_%", "BL_Count"), BackEnd!$F$5="Edible Oil", IF(BackEnd!$E$2=2, "EO_%", "EO_Count"), BackEnd!$F$5="Snacks", IF(BackEnd!$E$2=2, "SK_%", "SK_Count"), BackEnd!$F$5="Condiment Mixes", IF(BackEnd!$E$2=2, "CM_%", "CM_Count"), BackEnd!$F$5="Wet Hair", IF(BackEnd!$E$2=2, "WH_%", "WH_Count"), BackEnd!$F$5="Dry Hair", IF(BackEnd!$E$2=2, "DH_%", "DH_Count"), BackEnd!$F$5="Toilet Cleaner", IF(BackEnd!$E$2=2, "TC_%", "TC_Count") ) & "'!A" & MATCH( BackEnd!B13, INDIRECT("'" & _xlfn.IFS( BackEnd!$F$5="Noodles", IF(BackEnd!$E$2=2, "N_%", "N_Count"), BackEnd!$F$5="Toothpaste", IF(BackEnd!$E$2=2, "TP_%", "TP_Count"), BackEnd!$F$5="Breakfast Cereal", IF(BackEnd!$E$2=2, "BC_%", "BC_Count"), BackEnd!$F$5="Bleach", IF(BackEnd!$E$2=2, "BL_%", "BL_Count"), BackEnd!$F$5="Edible Oil", IF(BackEnd!$E$2=2, "EO_%", "EO_Count"), BackEnd!$F$5="Snacks", IF(BackEnd!$E$2=2, "SK_%", "SK_Count"), BackEnd!$F$5="Condiment Mixes", IF(BackEnd!$E$2=2, "CM_%", "CM_Count"), BackEnd!$F$5="Wet Hair", IF(BackEnd!$E$2=2, "WH_%", "WH_Count"), BackEnd!$F$5="Dry Hair", IF(BackEnd!$E$2=2, "DH_%", "DH_Count"), BackEnd!$F$5="Toilet Cleaner", IF(BackEnd!$E$2=2, "TC_%", "TC_Count") ) & "'!A:A" ), 0 ), BackEnd!B13 ),"")} | D17: =IF(BackEnd!C13="","",BackEnd!C13) -> #REF!
C18: {=IFERROR(HYPERLINK( "#'" & _xlfn.IFS( BackEnd!$F$5="Noodles", IF(BackEnd!$E$2=2, "N_%", "N_Count"), BackEnd!$F$5="Toothpaste", IF(BackEnd!$E$2=2, "TP_%", "TP_Count"), BackEnd!$F$5="Breakfast Cereal", IF(BackEnd!$E$2=2, "BC_%", "BC_Count"), BackEnd!$F$5="Bleach", IF(BackEnd!$E$2=2, "BL_%", "BL_Count"), BackEnd!$F$5="Edible Oil", IF(BackEnd!$E$2=2, "EO_%", "EO_Count"), BackEnd!$F$5="Snacks", IF(BackEnd!$E$2=2, "SK_%", "SK_Count"), BackEnd!$F$5="Condiment Mixes", IF(BackEnd!$E$2=2, "CM_%", "CM_Count"), BackEnd!$F$5="Wet Hair", IF(BackEnd!$E$2=2, "WH_%", "WH_Count"), BackEnd!$F$5="Dry Hair", IF(BackEnd!$E$2=2, "DH_%", "DH_Count"), BackEnd!$F$5="Toilet Cleaner", IF(BackEnd!$E$2=2, "TC_%", "TC_Count") ) & "'!A" & MATCH( BackEnd!B14, INDIRECT("'" & _xlfn.IFS( BackEnd!$F$5="Noodles", IF(BackEnd!$E$2=2, "N_%", "N_Count"), BackEnd!$F$5="Toothpaste", IF(BackEnd!$E$2=2, "TP_%", "TP_Count"), BackEnd!$F$5="Breakfast Cereal", IF(BackEnd!$E$2=2, "BC_%", "BC_Count"), BackEnd!$F$5="Bleach", IF(BackEnd!$E$2=2, "BL_%", "BL_Count"), BackEnd!$F$5="Edible Oil", IF(BackEnd!$E$2=2, "EO_%", "EO_Count"), BackEnd!$F$5="Snacks", IF(BackEnd!$E$2=2, "SK_%", "SK_Count"), BackEnd!$F$5="Condiment Mixes", IF(BackEnd!$E$2=2, "CM_%", "CM_Count"), BackEnd!$F$5="Wet Hair", IF(BackEnd!$E$2=2, "WH_%", "WH_Count"), BackEnd!$F$5="Dry Hair", IF(BackEnd!$E$2=2, "DH_%", "DH_Count"), BackEnd!$F$5="Toilet Cleaner", IF(BackEnd!$E$2=2, "TC_%", "TC_Count") ) & "'!A:A" ), 0 ), BackEnd!B14 ),"")} | D18: =IF(BackEnd!C14="","",BackEnd!C14) -> #REF!
C19: {=IFERROR(HYPERLINK( "#'" & _xlfn.IFS( BackEnd!$F$5="Noodles", IF(BackEnd!$E$2=2, "N_%", "N_Count"), BackEnd!$F$5="Toothpaste", IF(BackEnd!$E$2=2, "TP_%", "TP_Count"), BackEnd!$F$5="Breakfast Cereal", IF(BackEnd!$E$2=2, "BC_%", "BC_Count"), BackEnd!$F$5="Bleach", IF(BackEnd!$E$2=2, "BL_%", "BL_Count"), BackEnd!$F$5="Edible Oil", IF(BackEnd!$E$2=2, "EO_%", "EO_Count"), BackEnd!$F$5="Snacks", IF(BackEnd!$E$2=2, "SK_%", "SK_Count"), BackEnd!$F$5="Condiment Mixes", IF(BackEnd!$E$2=2, "CM_%", "CM_Count"), BackEnd!$F$5="Wet Hair", IF(BackEnd!$E$2=2, "WH_%", "WH_Count"), BackEnd!$F$5="Dry Hair", IF(BackEnd!$E$2=2, "DH_%", "DH_Count"), BackEnd!$F$5="Toilet Cleaner", IF(BackEnd!$E$2=2, "TC_%", "TC_Count") ) & "'!A" & MATCH( BackEnd!B15, INDIRECT("'" & _xlfn.IFS( BackEnd!$F$5="Noodles", IF(BackEnd!$E$2=2, "N_%", "N_Count"), BackEnd!$F$5="Toothpaste", IF(BackEnd!$E$2=2, "TP_%", "TP_Count"), BackEnd!$F$5="Breakfast Cereal", IF(BackEnd!$E$2=2, "BC_%", "BC_Count"), BackEnd!$F$5="Bleach", IF(BackEnd!$E$2=2, "BL_%", "BL_Count"), BackEnd!$F$5="Edible Oil", IF(BackEnd!$E$2=2, "EO_%", "EO_Count"), BackEnd!$F$5="Snacks", IF(BackEnd!$E$2=2, "SK_%", "SK_Count"), BackEnd!$F$5="Condiment Mixes", IF(BackEnd!$E$2=2, "CM_%", "CM_Count"), BackEnd!$F$5="Wet Hair", IF(BackEnd!$E$2=2, "WH_%", "WH_Count"), BackEnd!$F$5="Dry Hair", IF(BackEnd!$E$2=2, "DH_%", "DH_Count"), BackEnd!$F$5="Toilet Cleaner", IF(BackEnd!$E$2=2, "TC_%", "TC_Count") ) & "'!A:A" ), 0 ), BackEnd!B15 ),"")} | D19: =IF(BackEnd!C15="","",BackEnd!C15) -> #REF!
C20: {=IFERROR(HYPERLINK( "#'" & _xlfn.IFS( BackEnd!$F$5="Noodles", IF(BackEnd!$E$2=2, "N_%", "N_Count"), BackEnd!$F$5="Toothpaste", IF(BackEnd!$E$2=2, "TP_%", "TP_Count"), BackEnd!$F$5="Breakfast Cereal", IF(BackEnd!$E$2=2, "BC_%", "BC_Count"), BackEnd!$F$5="Bleach", IF(BackEnd!$E$2=2, "BL_%", "BL_Count"), BackEnd!$F$5="Edible Oil", IF(BackEnd!$E$2=2, "EO_%", "EO_Count"), BackEnd!$F$5="Snacks", IF(BackEnd!$E$2=2, "SK_%", "SK_Count"), BackEnd!$F$5="Condiment Mixes", IF(BackEnd!$E$2=2, "CM_%", "CM_Count"), BackEnd!$F$5="Wet Hair", IF(BackEnd!$E$2=2, "WH_%", "WH_Count"), BackEnd!$F$5="Dry Hair", IF(BackEnd!$E$2=2, "DH_%", "DH_Count"), BackEnd!$F$5="Toilet Cleaner", IF(BackEnd!$E$2=2, "TC_%", "TC_Count") ) & "'!A" & MATCH( BackEnd!B16, INDIRECT("'" & _xlfn.IFS( BackEnd!$F$5="Noodles", IF(BackEnd!$E$2=2, "N_%", "N_Count"), BackEnd!$F$5="Toothpaste", IF(BackEnd!$E$2=2, "TP_%", "TP_Count"), BackEnd!$F$5="Breakfast Cereal", IF(BackEnd!$E$2=2, "BC_%", "BC_Count"), BackEnd!$F$5="Bleach", IF(BackEnd!$E$2=2, "BL_%", "BL_Count"), BackEnd!$F$5="Edible Oil", IF(BackEnd!$E$2=2, "EO_%", "EO_Count"), BackEnd!$F$5="Snacks", IF(BackEnd!$E$2=2, "SK_%", "SK_Count"), BackEnd!$F$5="Condiment Mixes", IF(BackEnd!$E$2=2, "CM_%", "CM_Count"), BackEnd!$F$5="Wet Hair", IF(BackEnd!$E$2=2, "WH_%", "WH_Count"), BackEnd!$F$5="Dry Hair", IF(BackEnd!$E$2=2, "DH_%", "DH_Count"), BackEnd!$F$5="Toilet Cleaner", IF(BackEnd!$E$2=2, "TC_%", "TC_Count") ) & "'!A:A" ), 0 ), BackEnd!B16 ),"")} | D20: =IF(BackEnd!C16="","",BackEnd!C16) -> #REF!
C21: {=IFERROR(HYPERLINK( "#'" & _xlfn.IFS( BackEnd!$F$5="Noodles", IF(BackEnd!$E$2=2, "N_%", "N_Count"), BackEnd!$F$5="Toothpaste", IF(BackEnd!$E$2=2, "TP_%", "TP_Count"), BackEnd!$F$5="Breakfast Cereal", IF(BackEnd!$E$2=2, "BC_%", "BC_Count"), BackEnd!$F$5="Bleach", IF(BackEnd!$E$2=2, "BL_%", "BL_Count"), BackEnd!$F$5="Edible Oil", IF(BackEnd!$E$2=2, "EO_%", "EO_Count"), BackEnd!$F$5="Snacks", IF(BackEnd!$E$2=2, "SK_%", "SK_Count"), BackEnd!$F$5="Condiment Mixes", IF(BackEnd!$E$2=2, "CM_%", "CM_Count"), BackEnd!$F$5="Wet Hair", IF(BackEnd!$E$2=2, "WH_%", "WH_Count"), BackEnd!$F$5="Dry Hair", IF(BackEnd!$E$2=2, "DH_%", "DH_Count"), BackEnd!$F$5="Toilet Cleaner", IF(BackEnd!$E$2=2, "TC_%", "TC_Count") ) & "'!A" & MATCH( BackEnd!B17, INDIRECT("'" & _xlfn.IFS( BackEnd!$F$5="Noodles", IF(BackEnd!$E$2=2, "N_%", "N_Count"), BackEnd!$F$5="Toothpaste", IF(BackEnd!$E$2=2, "TP_%", "TP_Count"), BackEnd!$F$5="Breakfast Cereal", IF(BackEnd!$E$2=2, "BC_%", "BC_Count"), BackEnd!$F$5="Bleach", IF(BackEnd!$E$2=2, "BL_%", "BL_Count"), BackEnd!$F$5="Edible Oil", IF(BackEnd!$E$2=2, "EO_%", "EO_Count"), BackEnd!$F$5="Snacks", IF(BackEnd!$E$2=2, "SK_%", "SK_Count"), BackEnd!$F$5="Condiment Mixes", IF(BackEnd!$E$2=2, "CM_%", "CM_Count"), BackEnd!$F$5="Wet Hair", IF(BackEnd!$E$2=2, "WH_%", "WH_Count"), BackEnd!$F$5="Dry Hair", IF(BackEnd!$E$2=2, "DH_%", "DH_Count"), BackEnd!$F$5="Toilet Cleaner", IF(BackEnd!$E$2=2, "TC_%", "TC_Count") ) & "'!A:A" ), 0 ), BackEnd!B17 ),"")} | D21: =IF(BackEnd!C17="","",BackEnd!C17) -> #REF!
... C69: {=IFERROR(HYPERLINK( "#'" & _xlfn.IFS( BackEnd!$F$5="Noodles", IF(BackEnd!$E$2=2, "N_%", "N_Count"), BackEnd!$F$5="Toothpaste", IF(BackEnd!$E$2=2, "TP_%", "TP_Count"), BackEnd!$F$5="Breakfast Cereal", IF(BackEnd!$E$2=2, "BC_%", "BC_Count"), BackEnd!$F$5="Bleach", IF(BackEnd!$E$2=2, "BL_%", "BL_Count"), BackEnd!$F$5="Edible Oil", IF(BackEnd!$E$2=2, "EO_%", "EO_Count"), BackEnd!$F$5="Snacks", IF(BackEnd!$E$2=2, "SK_%", "SK_Count"), BackEnd!$F$5="Condiment Mixes", IF(BackEnd!$E$2=2, "CM_%", "CM_Count"), BackEnd!$F$5="Wet Hair", IF(BackEnd!$E$2=2, "WH_%", "WH_Count"), BackEnd!$F$5="Dry Hair", IF(BackEnd!$E$2=2, "DH_%", "DH_Count"), BackEnd!$F$5="Toilet Cleaner", IF(BackEnd!$E$2=2, "TC_%", "TC_Count") ) & "'!A" & MATCH( BackEnd!B65, INDIRECT("'" & _xlfn.IFS( BackEnd!$F$5="Noodles", IF(BackEnd!$E$2=2, "N_%", "N_Count"), BackEnd!$F$5="Toothpaste", IF(BackEnd!$E$2=2, "TP_%", "TP_Count"), BackEnd!$F$5="Breakfast Cereal", IF(BackEnd!$E$2=2, "BC_%", "BC_Count"), BackEnd!$F$5="Bleach", IF(BackEnd!$E$2=2, "BL_%", "BL_Count"), BackEnd!$F$5="Edible Oil", IF(BackEnd!$E$2=2, "EO_%", "EO_Count"), BackEnd!$F$5="Snacks", IF(BackEnd!$E$2=2, "SK_%", "SK_Count"), BackEnd!$F$5="Condiment Mixes", IF(BackEnd!$E$2=2, "CM_%", "CM_Count"), BackEnd!$F$5="Wet Hair", IF(BackEnd!$E$2=2, "WH_%", "WH_Count"), BackEnd!$F$5="Dry Hair", IF(BackEnd!$E$2=2, "DH_%", "DH_Count"), BackEnd!$F$5="Toilet Cleaner", IF(BackEnd!$E$2=2, "TC_%", "TC_Count") ) & "'!A:A" ), 0 ), BackEnd!B65 ),"")} | D69: =IF(BackEnd!C65="","",BackEnd!C65)

Sheet BackEnd
E1: Radio Button(N AND % Count) | M1: Noodles | R1: Toothpaste | W1: Breakfast Cereal | AB1: Bleach | AF1: Edible Oil | AK1: Snacks | AP1: Condiment Mixes | AU1: Wet Hair | AZ1: Dry Hair | BE1: Toilet Cleaner
E2: 1 | H2: 1 | I2: Noodles | M2: Table 1 | N2: N_BAU1A. When you think of Instant Noodles, what brand comes to your mind first? | O2: {=INDEX(#REF!,MATCH(BackEnd!N2,#REF!,0)+6,3)} -> #REF! | R2: Table 1 | S2: TP_BAU1A. When you think of Toothpaste, what brand comes to your mind first? | T2: {=INDEX(#REF!,MATCH(BackEnd!S2,#REF!,0)+6,3)} -> #REF! | W2: Table 1 | X2: BC_BAU1A. When you think of Breakfast Breakfast Cereals, what brand comes to your mind first? | Y2: {=INDEX(#REF!,MATCH(BackEnd!X2,#REF!,0)+6,3)} -> #REF! | AB2: Table 1 | AC2: BL_BAU1A. When you think of Bleach, what brand comes to your mind first? | AD2: {=INDEX(#REF!,MATCH(BackEnd!AC2,#REF!,0)+6,3)} -> #REF! | AF2: Table 1 | AG2: EO_BAU1A. When you think of Cooking Oil, what brand comes to your mind first? | AH2: {=INDEX(#REF!,MATCH(BackEnd!AG2,#REF!,0)+6,3)} -> #REF! | AK2: Table 1 | AL2: SK_BAU1A. When you think of Snacks, what brand comes to your mind first? | AM2: {=INDEX(#REF!,MATCH(BackEnd!AL2,#REF!,0)+6,3)} -> #REF! | AP2: Table 1 | AQ2: CM_BAU1A. When you think of Condiments, what brand comes to your mind first? | AR2: {=INDEX(#REF!,MATCH(BackEnd!AQ2,#REF!,0)+6,3)} -> #REF! | AU2: Table 1 | AV2: WH_BAU1A. When you think of Hair Care Products, what brand comes to your mind first? | AW2: {=INDEX(#REF!,MATCH(BackEnd!AV2,#REF!,0)+0,3)} -> #REF! | AZ2: Table 1 | BA2: DH_BAU1A. When you think of Hair Extensions, what brand comes to your mind first? | BB2: {=INDEX(#REF!,MATCH(BackEnd!BA2,#REF!,0)+6,3)} -> #REF! | BE2: Table 1 | BF2: TC_BAU1A. When you think of Toilet cleaners, what brand comes to your mind first? | BG2: {=INDEX(#REF!,MATCH(BackEnd!BF2,#REF!,0)+6,3)} -> #REF!
H3: 2 | I3: Toothpaste | M3: Table 2 | N3: N_BAU1B. What other brands of Instant Noodles can you think of? Any other? Please mention as many brands as you can think of? | O3: {=INDEX(#REF!,MATCH(BackEnd!N3,#REF!,0)+6,3)} -> #REF! | R3: Table 2 | S3: TP_BAU1B. What other brands of Toothpastes can you think of? Please mention as many brands as you can think of: | T3: {=INDEX(#REF!,MATCH(BackEnd!S3,#REF!,0)+6,3)} -> #REF! | W3: Table 2 | X3: BC_BAU1B. What other brands of Breakfast Cereals can you think of? Any other? Please mention as many brands as you can think of: | Y3: {=INDEX(#REF!,MATCH(BackEnd!X3,#REF!,0)+6,3)} -> #REF! | AB3: Table 2 | AC3: BL_BAU1B. What other brands of Bleach can you think of? Any other? Please mention as many brands as you can think of: | AD3: {=INDEX(#REF!,MATCH(BackEnd!AC3,#REF!,0)+6,3)} -> #REF! | AF3: Table 2 | AG3: EO_BAU1B. What other brands of Cooking Oils can you think of? Please mention as many as you can. | AH3: {=INDEX(#REF!,MATCH(BackEnd!AG3,#REF!,0)+6,3)} -> #REF! | AK3: Table 2 | AL3: SK_BAU1B. What other brands of Snacks can you think of? Any other? Please mention as many brands as you can think?. | AM3: {=INDEX(#REF!,MATCH(BackEnd!AL3,#REF!,0)+6,3)} -> #REF! | AP3: Table 2 | AQ3: CM_BAU1B. What other brands of Condiments can you think of? Any other? Please mention as many brands as you can think of | AR3: {=INDEX(#REF!,MATCH(BackEnd!AQ3,#REF!,0)+6,3)} -> #REF! | AU3: Table 2 | AV3: WH_BAU1B. What other brands of Hair Care Products can you think of? Any other? Please mention as many brands as you can think of: | AW3: {=INDEX(#REF!,MATCH(BackEnd!AV3,#REF!,0)+6,3)} -> #REF! | AZ3: Table 2 | BA3: DH_BAU1B. What other brands of Hair Extensions can you think of? Please mention as many as you can | BB3: {=INDEX(#REF!,MATCH(BackEnd!BA3,#REF!,0)+6,3)} -> #REF! | BE3: Table 2 | BF3: TC_BAU1B. What other brands of Toilet cleaners can you think of? Any other? Please mention as many brands as you can think of | BG3: {=INDEX(#REF!,MATCH(BackEnd!BF3,#REF!,0)+6,3)} -> #REF!
E4: Dropdown(Category Selection) | H4: 3 | I4: Breakfast Cereal | M4: Table 3 | N4: N_BAU1C. Which instant Noodles brand first comes to your mind when you think of advertisements in the past 3 ROLL_MONTHs? | O4: {=INDEX(#REF!,MATCH(BackEnd!N4,#REF!,0)+6,3)} -> #REF! | R4: Table 3 | S4: TP_BAU1C. Which Toothpastes brand first comes to your mind when you think of advertisements of brands of Toothpastes in the past 3 ROLL_MONTHs? | T4: {=INDEX(#REF!,MATCH(BackEnd!S4,#REF!,0)+6,3)} -> #REF! | W4: Table 3 | X4: BC_BAU1C. Which Cereal brand first comes to your mind when you think of advertisements of brands of Bleach in the past 3 ROLL_MONTHs? | Y4: {=INDEX(#REF!,MATCH(BackEnd!X4,#REF!,0)+6,3)} -> #REF! | AB4: Table 3 | AC4: BL_BAU1C. Which Bleach brand first comes to your mind when you think of advertisements of brands of Bleach in the past 3 ROLL_MONTHs? | AD4: {=INDEX(#REF!,MATCH(BackEnd!AC4,#REF!,0)+6,3)} -> #REF! | AF4: Table 3 | AG4: EO_BAU1C. Which Cooking Oils brand first comes to your mind when you think of advertisements in the past 3 ROLL_MONTHs? | AH4: {=INDEX(#REF!,MATCH(BackEnd!AG4,#REF!,0)+6,3)} -> #REF! | AK4: Table 3 | AL4: SK_BAU1C. Which Snack brand first comes to your mind when you think of advertisements of brands of Bleach in the past 3 ROLL_MONTHs? | AM4: {=INDEX(#REF!,MATCH(BackEnd!AL4,#REF!,0)+6,3)} -> #REF! | AP4: Table 3 | AQ4: CM_BAU1C. Which Condiment mix brand first comes to your mind when you think of advertisements of brands of Condiments in the past 3 ROLL_MONTHs? | AR4: {=INDEX(#REF!,MATCH(BackEnd!AQ4,#REF!,0)+6,3)} -> #REF! | AU4: Table 3 | AV4: WH_BAU1C. Which Hair Care Product brand first comes to your mind when you think of advertisements of brands of Bleach in the past 3 ROLL_MONTHs? | AW4: {=INDEX(#REF!,MATCH(BackEnd!AV4,#REF!,0)+6,3)} -> #REF! | AZ4: Table 3 | BA4: DH_BAU1C. Which Hair Extension brand first comes to your mind when you think of advertisements in the past 3 ROLL_MONTH? | BB4: {=INDEX(#REF!,MATCH(BackEnd!BA4,#REF!,0)+6,3)} -> #REF! | BE4: Table 3 | BF4: TC_BAU1C. Which Toilet cleaner brand first comes to your mind when you think of advertisements of brands of Bleach in the past 3 ROLL_MONTHs? | BG4: {=INDEX(#REF!,MATCH(BackEnd!BF4,#REF!,0)+6,3)} -> #REF!
E5: 1 | F5: =_xlfn.XLOOKUP(E5,H:H,I:I) -> Noodles | H5: 4 | I5: Bleach | M5: Table 4 | N5: N_BAU1D. Which other brand of instant Noodles advertisement are you aware of? | O5: {=INDEX(#REF!,MATCH(BackEnd!N5,#REF!,0)+6,3)} -> #REF! | R5: Table 4 | S5: TP_BAU1D. Which other brands come to mind when you think of advertisements of Toothpastes in the past 3 ROLL_MONTHs? | T5: {=INDEX(#REF!,MATCH(BackEnd!S5,#REF!,0)+6,3)} -> #REF! | W5: Table 4 | X5: BC_BAU1D. Which other brand of Breakfast Cereals advertisement are you aware of? | Y5: {=INDEX(#REF!,MATCH(BackEnd!X5,#REF!,0)+6,3)} -> #REF! | AB5: Table 4 | AC5: BL_BAU1D. Which other brand of Bleach advertisement are you aware of? | AD5: {=INDEX(#REF!,MATCH(BackEnd!AC5,#REF!,0)+6,3)} -> #REF! | AF5: Table 4 | AG5: EO_BAU1D. Which other brands of Cooking Oils advertisements are you aware of? | AH5: {=INDEX(#REF!,MATCH(BackEnd!AG5,#REF!,0)+6,3)} -> #REF! | AK5: Table 4 | AL5: SK_BAU1D. Which other brand of Snacks advertisement are you aware of?. | AM5: {=INDEX(#REF!,MATCH(BackEnd!AL5,#REF!,0)+6,3)} -> #REF! | AP5: Table 4 | AQ5: CM_BAU1D. Which other brand of Condiments advertisement are you aware of | AR5: {=INDEX(#REF!,MATCH(BackEnd!AQ5,#REF!,0)+6,3)} -> #REF! | AU5: Table 4 | AV5: WH_BAU1D. Which other brand of Hair Care Products advertisement are you aware of? | AW5: {=INDEX(#REF!,MATCH(BackEnd!AV5,#REF!,0)+0,3)} -> #REF! | AZ5: Table 4 | BA5: DH_BAU1D. Which other brand of Hair Extensions advertisement are you aware of | BB5: {=INDEX(#REF!,MATCH(BackEnd!BA5,#REF!,0)+6,3)} -> #REF! | BE5: Table 4 | BF5: TC_BAU1D. Which other brand of Toilet cleaners advertisement are you aware of? | BG5: {=INDEX(#REF!,MATCH(BackEnd!BF5,#REF!,0)+6,3)} -> #REF!
A6: {=IF($E$5=1,M2:O53,IF($E$5=2,R2:T43,IF($E$5=3,W2:Y59,IF($E$5=4,AB2:AD35,IF($E$5=5,AF2:AH42,IF($E$5=6,AK2:AM44,IF($E$5=7,AP2:AR38,IF($E$5=8,AU2:AW43,IF($E$5=9,AZ2:BB38,IF($E$5=10,BE2:BG37))))))))))} -> Table 1 | B6: N_BAU1A. When you think of Instant Noodles, what brand comes to your mind first? | C6: #REF! | H6: 5 | I6: Edible Oil | M6: Table 5 | N6: N_BAU2. Please take a look at this and tell me which brand of Instant Noodles are you aware of? | O6: {=INDEX(#REF!,MATCH(BackEnd!N6,#REF!,0)+6,3)} -> #REF! | R6: Table 5 | S6: TP_BAU2. Please tell me which brand of Toothpastes are you aware of? | T6: {=INDEX(#REF!,MATCH(BackEnd!S6,#REF!,0)+6,3)} -> #REF! | W6: Table 5 | X6: BC_BAU2. Please take a look at this and tell me which brand of Breakfast Cereals are you aware of? | Y6: {=INDEX(#REF!,MATCH(BackEnd!X6,#REF!,0)+6,3)} -> #REF! | AB6: Table 5 | AC6: BL_BAU2. Please take a look at this and tell me which brand of Bleach are you aware of? | AD6: {=INDEX(#REF!,MATCH(BackEnd!AC6,#REF!,0)+6,3)} -> #REF! | AF6: Table 5 | AG6: EO_BAU2. Please tell me which brands of Cooking Oils you are aware of. | AH6: {=INDEX(#REF!,MATCH(BackEnd!AG6,#REF!,0)+6,3)} -> #REF! | AK6: Table 5 | AL6: SK_BAU2. Please take a look at this and tell me which brand of Snacks are you aware of?. | AM6: {=INDEX(#REF!,MATCH(BackEnd!AL6,#REF!,0)+6,3)} -> #REF! | AP6: Table 5 | AQ6: CM_BAU2. Please take a look at this and tell me which brand of Condiments are you aware of? | AR6: {=INDEX(#REF!,MATCH(BackEnd!AQ6,#REF!,0)+6,3)} -> #REF! | AU6: Table 5 | AV6: WH_BAU2. Please take a look at this and tell me which brand of Hair Care Products are you aware of? | AW6: {=INDEX(#REF!,MATCH(BackEnd!AV6,#REF!,0)+0,3)} -> #REF! | AZ6: Table 5 | BA6: DH_BAU2. Please take a look and tell me which brand of Hair Extensions you are aware of | BB6: {=INDEX(#REF!,MATCH(BackEnd!BA6,#REF!,0)+6,3)} -> #REF! | BE6: Table 5 | BF6: TC_BAU2. Please take a look at this and tell me which brand of Toilet cleaners are you aware of? | BG6: {=INDEX(#REF!,MATCH(BackEnd!BF6,#REF!,0)+0,3)} -> #REF!
A7: Table 2 | B7: N_BAU1B. What other brands of Instant Noodles can you think of? Any other? Please mention as many brands as you can think of? | C7: #REF! | H7: 6 | I7: Snacks | M7: Table 6 | N7: N_BAU3. Which other brands in this list do you remember seeing, reading or hearing any advertising for recently? | O7: {=INDEX(#REF!,MATCH(BackEnd!N7,#REF!,0)+6,3)} -> #REF! | R7: Table 6 | S7: TP_BAU3. Which other brands in this list do you remember seeing or hearing advertising for recently? | T7: {=INDEX(#REF!,MATCH(BackEnd!S7,#REF!,0)+6,3)} -> #REF! | W7: Table 6 | X7: BC_BAU3. Which other brands in this list do you remember having seen, read or heard any advertising or activities for recently? | Y7: {=INDEX(#REF!,MATCH(BackEnd!X7,#REF!,0)+6,3)} -> #REF! | AB7: Table 6 | AC7: BL_BAU3. Which other brands in this list do you remember having seen, read or heard any advertising or activities for recently? | AD7: {=INDEX(#REF!,MATCH(BackEnd!AC7,#REF!,0)+6,3)} -> #REF! | AF7: Table 6 | AG7: EO_BAU3. Which other brands in this list do you remember seeing or hearing advertising for recently? | AH7: {=INDEX(#REF!,MATCH(BackEnd!AG7,#REF!,0)+6,3)} -> #REF! | AK7: Table 6 | AL7: SK_BAU3. Which other brands in this list do you remember having seen, read or heard any advertising or activities for recently | AM7: {=INDEX(#REF!,MATCH(BackEnd!AL7,#REF!,0)+6,3)} -> #REF! | AP7: Table 6 | AQ7: CM_BAU3. Which other brands in this list do you remember having seen, read or heard any advertising or activities for recently | AR7: {=INDEX(#REF!,MATCH(BackEnd!AQ7,#REF!,0)+6,3)} -> #REF! | AU7: Table 6 | AV7: WH_BAU3. Which other brands in this list do you remember having seen, read or heard any advertising or activities for recently? | AW7: {=INDEX(#REF!,MATCH(BackEnd!AV7,#REF!,0)+0,3)} -> #REF! | AZ7: Table 6 | BA7: DH_BAU3. Which other brands in this list do you remember seeing or hearing advertised recently | BB7: {=INDEX(#REF!,MATCH(BackEnd!BA7,#REF!,0)+6,3)} -> #REF! | BE7: Table 6 | BF7: TC_BAU3. Which other brands in this list do you remember having seen, read or heard any advertising or activities for recently | BG7: {=INDEX(#REF!,MATCH(BackEnd!BF7,#REF!,0)+6,3)} -> #REF!
A8: Table 3 | B8: N_BAU1C. Which instant Noodles brand first comes to your mind when you think of advertisements in the past 3 ROLL_MONTHs? | C8: #REF! | H8: 7 | I8: Condiment Mixes | M8: Table 7 | N8: N_BAU4. And where have you seen or heard any advertisement/communication about Chikki | O8: {=INDEX(#REF!,MATCH(BackEnd!N8,#REF!,0)+6,3)} -> #REF! | R8: Table 7 | S8: TP_BAU4. Where have you seen or heard any advertisement about Close Up? | T8: {=INDEX(#REF!,MATCH(BackEnd!S8,#REF!,0)+6,3)} -> #REF! | W8: Table 7 | X8: BC_BAU4. Where have you seen or heard any advertisement/communication about Blue Boat | Y8: {=INDEX(#REF!,MATCH(BackEnd!X8,#REF!,0)+6,3)} -> #REF! | AB8: Table 7 | AC8: BL_BAU4. Where have you seen or heard any advertisement/communication about JIK | AD8: {=INDEX(#REF!,MATCH(BackEnd!AC8,#REF!,0)+6,3)} -> #REF! | AF8: Table 7 | AG8: EO_BAU4. Where have you seen or heard any advertisement about Power Oil? | AH8: {=INDEX(#REF!,MATCH(BackEnd!AG8,#REF!,0)+6,3)} -> #REF! | AK8: Table 7 | AL8: SK_BAU4. And where have you seen or heard any advertisement/communication about Gala?. | AM8: {=INDEX(#REF!,MATCH(BackEnd!AL8,#REF!,0)+6,3)} -> #REF! | AP8: Table 7 | AQ8: CM_BAU4. And where have you seen or heard any advertisement/communication about Maggi Cubes | AR8: {=INDEX(#REF!,MATCH(BackEnd!AQ8,#REF!,0)+6,3)} -> #REF! | AU8: Table 7 | AV8: WH_BAU4. And where have you seen or heard any advertisement/communication about PROFECTIV MEGA GROWTH | AW8: {=INDEX(#REF!,MATCH(BackEnd!AV8,#REF!,0)+6,3)} -> #REF! | AZ8: Table 7 | BA8: DH_BAU4. Where have you seen or heard any advertisement about AMIGO | BB8: {=INDEX(#REF!,MATCH(BackEnd!BA8,#REF!,0)+6,3)} -> #REF! | BE8: Table 7 | BF8: TC_BAU4. And where have you seen or heard any advertisement/communication about Harpic Toilet Cleaner | BG8: {=INDEX(#REF!,MATCH(BackEnd!BF8,#REF!,0)+6,3)} -> #REF!
A9: Table 4 | B9: N_BAU1D. Which other brand of instant Noodles advertisement are you aware of? | C9: #REF! | H9: 8 | I9: Wet Hair | M9: Table 8 | N9: N_BAU4. And where have you seen or heard any advertisement/communication about Cherie | O9: {=INDEX(#REF!,MATCH(BackEnd!N9,#REF!,0)+6,3)} -> #REF! | R9: Table 8 | S9: TP_BAU4. Where have you seen or heard any advertisement about Colgate? | T9: {=INDEX(#REF!,MATCH(BackEnd!S9,#REF!,0)+6,3)} -> #REF! | W9: Table 8 | X9: BC_BAU4. Where have you seen or heard any advertisement/communication about Candia Cereal | Y9: {=INDEX(#REF!,MATCH(BackEnd!X9,#REF!,0)+6,3)} -> #REF! | AB9: Table 8 | AC9: BL_BAU4. Where have you seen or heard any advertisement/communication about Hypo | AD9: {=INDEX(#REF!,MATCH(BackEnd!AC9,#REF!,0)+6,3)} -> #REF! | AF9: Table 8 | AG9: EO_BAU4. Where have you seen or heard any advertisement about Mamador? | AH9: {=INDEX(#REF!,MATCH(BackEnd!AG9,#REF!,0)+6,3)} -> #REF! | AK9: Table 8 | AL9: SK_BAU4. And where have you seen or heard any advertisement/communication about Minimie Chinchin?. | AM9: {=INDEX(#REF!,MATCH(BackEnd!AL9,#REF!,0)+6,3)} -> #REF! | AP9: Table 8 | AQ9: CM_BAU4. And where have you seen or heard any advertisement/communication about Knorr Cubes | AR9: {=INDEX(#REF!,MATCH(BackEnd!AQ9,#REF!,0)+6,3)} -> #REF! | AU9: Table 8 | AV9: WH_BAU4. And where have you seen or heard any advertisement/communication about ORS OLIVE OIL | AW9: {=INDEX(#REF!,MATCH(BackEnd!AV9,#REF!,0)+6,3)} -> #REF! | AZ9: Table 8 | BA9: DH_BAU4. Where have you seen or heard any advertisement about BELLA | BB9: {=INDEX(#REF!,MATCH(BackEnd!BA9,#REF!,0)+6,3)} -> #REF! | BE9: Table 8 | BF9: TC_BAU4. And where have you seen or heard any advertisement/communication about Hypo Toilet Cleaner | BG9: {=INDEX(#REF!,MATCH(BackEnd!BF9,#REF!,0)+6,3)} -> #REF!
A10: Table 5 | B10: N_BAU2. Please take a look at this and tell me which brand of Instant Noodles are you aware of? | C10: #REF! | H10: 9 | I10: Dry Hair | M10: Table 9 | N10: N_BAU4. And where have you seen or heard any advertisement/communication about Golden Penny | O10: {=INDEX(#REF!,MATCH(BackEnd!N10,#REF!,0)+6,3)} -> #REF! | R10: Table 9 | S10: TP_BAU4. Where have you seen or heard any advertisement about Dabur? | T10: {=INDEX(#REF!,MATCH(BackEnd!S10,#REF!,0)+6,3)} -> #REF! | W10: Table 9 | X10: BC_BAU4. Where have you seen or heard any advertisement/communication about Choco Milo | Y10: {=INDEX(#REF!,MATCH(BackEnd!X10,#REF!,0)+6,3)} -> #REF! | AB10: Table 9 | AC10: BL_BAU4. Where have you seen or heard any advertisement/communication about Clor | AD10: {=INDEX(#REF!,MATCH(BackEnd!AC10,#REF!,0)+6,3)} -> #REF! | AF10: Table 9 | AG10: EO_BAU4. Where have you seen or heard any advertisement about Golden Terra? | AH10: {=INDEX(#REF!,MATCH(BackEnd!AG10,#REF!,0)+6,3)} -> #REF! | AK10: Table 9 | AL10: SK_BAU4. And where have you seen or heard any advertisement/communication about Munch It?. | AM10: {=INDEX(#REF!,MATCH(BackEnd!AL10,#REF!,0)+6,3)} -> #REF! | AP10: Table 9 | AQ10: CM_BAU4. And where have you seen or heard any advertisement/communication about Royco Seasoning | AR10: {=INDEX(#REF!,MATCH(BackEnd!AQ10,#REF!,0)+6,3)} -> #REF! | AU10: Table 9 | AV10: WH_BAU4. And where have you seen or heard any advertisement/communication about DARK AND LOVELY | AW10: {=INDEX(#REF!,MATCH(BackEnd!AV10,#REF!,0)+6,3)} -> #REF! | AZ10: Table 9 | BA10: DH_BAU4. Where have you seen or heard any advertisement about DARLING | BB10: {=INDEX(#REF!,MATCH(BackEnd!BA10,#REF!,0)+6,3)} -> #REF! | BE10: Table 9 | BF10: TC_BAU4. And where have you seen or heard any advertisement/communication about Kleansol Toilet Cleaner | BG10: {=INDEX(#REF!,MATCH(BackEnd!BF10,#REF!,0)+6,3)} -> #REF!
A11: Table 6 | B11: N_BAU3. Which other brands in this list do you remember seeing, reading or hearing any advertising for recently? | C11: #REF! | H11: 10 | I11: Toilet Cleaner | M11: Table 10 | N11: N_BAU4. And where have you seen or heard any advertisement/communication about Indomie | O11: {=INDEX(#REF!,MATCH(BackEnd!N11,#REF!,0)+6,3)} -> #REF! | R11: Table 10 | S11: TP_BAU4. Where have you seen or heard any advertisement about Euthymol? | T11: {=INDEX(#REF!,MATCH(BackEnd!S11,#REF!,0)+6,3)} -> #REF! | W11: Table 10 | X11: BC_BAU4. Where have you seen or heard any advertisement/communication about Crownfield Cornflakes | Y11: {=INDEX(#REF!,MATCH(BackEnd!X11,#REF!,0)+6,3)} -> #REF! | AB11: Table 10 | AC11: BL_BAU4. Where have you seen or heard any advertisement/communication about Kick | AD11: {=INDEX(#REF!,MATCH(BackEnd!AC11,#REF!,0)+6,3)} -> #REF! | AF11: Table 10 | AG11: EO_BAU4. Where have you seen or heard any advertisement about Active Gold? | AH11: {=INDEX(#REF!,MATCH(BackEnd!AG11,#REF!,0)+6,3)} -> #REF! | AK11: Table 10 | AL11: SK_BAU4. And where have you seen or heard any advertisement/communication about Rite | AM11: {=INDEX(#REF!,MATCH(BackEnd!AL11,#REF!,0)+6,3)} -> #REF! | AP11: Table 10 | AQ11: CM_BAU4. And where have you seen or heard any advertisement/communication about Addmie | AR11: {=INDEX(#REF!,MATCH(BackEnd!AQ11,#REF!,0)+6,3)} -> #REF! | AU11: Table 10 | AV11: WH_BAU4. And where have you seen or heard any advertisement/communication about ELAN | AW11: {=INDEX(#REF!,MATCH(BackEnd!AV11,#REF!,0)+6,3)} -> #REF! | AZ11: Table 10 | BA11: DH_BAU4. Where have you seen or heard any advertisement about LUSH | BB11: {=INDEX(#REF!,MATCH(BackEnd!BA11,#REF!,0)+6,3)} -> #REF! | BE11: Table 10 | BF11: TC_BAU4. And where have you seen or heard any advertisement/communication about Wind Toilet Cleaner | BG11: {=INDEX(#REF!,MATCH(BackEnd!BF11,#REF!,0)+6,3)} -> #REF!
A12: Table 7 | B12: N_BAU4. And where have you seen or heard any advertisement/communication about Chikki | C12: #REF! | M12: Table 11 | N12: N_BAU4. And where have you seen or heard any advertisement/communication about Mimee | O12: {=INDEX(#REF!,MATCH(BackEnd!N12,#REF!,0)+6,3)} -> #REF! | R12: Table 11 | S12: TP_BAU4. Where have you seen or heard any advertisement about Macleans? | T12: {=INDEX(#REF!,MATCH(BackEnd!S12,#REF!,0)+6,3)} -> #REF! | W12: Table 11 | X12: BC_BAU4. Where have you seen or heard any advertisement/communication about Frosted Flakes | Y12: {=INDEX(#REF!,MATCH(BackEnd!X12,#REF!,0)+6,3)} -> #REF! | AB12: Table 11 | AC12: BL_BAU4. Where have you seen or heard any advertisement/communication about Izola | AD12: {=INDEX(#REF!,MATCH(BackEnd!AC12,#REF!,0)+6,3)} -> #REF! | AF12: Table 11 | AG12: EO_BAU4. Where have you seen or heard any advertisement about Emperor? | AH12: {=INDEX(#REF!,MATCH(BackEnd!AG12,#REF!,0)+6,3)} -> #REF! | AK12: Table 11 | AL12: SK_BAU4. And where have you seen or heard any advertisement/communication about Bigi Snacks | AM12: {=INDEX(#REF!,MATCH(BackEnd!AL12,#REF!,0)+6,3)} -> #REF! | AP12: Table 11 | AQ12: CM_BAU4. And where have you seen or heard any advertisement/communication about Ducros Curry Powder | AR12: {=INDEX(#REF!,MATCH(BackEnd!AQ12,#REF!,0)+6,3)} -> #REF! | AU12: Table 11 | AV12: WH_BAU4. And where have you seen or heard any advertisement/communication about SUNNYPEACE (LAZINA) | AW12: {=INDEX(#REF!,MATCH(BackEnd!AV12,#REF!,0)+6,3)} -> #REF! | AZ12: Table 11 | BA12: DH_BAU4. Where have you seen or heard any advertisement about NOBLE | BB12: {=INDEX(#REF!,MATCH(BackEnd!BA12,#REF!,0)+6,3)} -> #REF! | BE12: Table 11 | BF12: TC_BAU4. And where have you seen or heard any advertisement/communication about Kleanmate Toilet Cleaner | BG12: {=INDEX(#REF!,MATCH(BackEnd!BF12,#REF!,0)+6,3)} -> #REF!
A13: Table 8 | B13: N_BAU4. And where have you seen or heard any advertisement/communication about Cherie | C13: #REF! | M13: Table 12 | N13: N_BAU4. And where have you seen or heard any advertisement/communication about Tummy Tummy | O13: {=INDEX(#REF!,MATCH(BackEnd!N13,#REF!,0)+6,3)} -> #REF! | R13: Table 12 | S13: TP_BAU4. Where have you seen or heard any advertisement about My My? | T13: {=INDEX(#REF!,MATCH(BackEnd!S13,#REF!,0)+6,3)} -> #REF! | W13: Table 12 | X13: BC_BAU4. Where have you seen or heard any advertisement/communication about Golden Morn | Y13: {=INDEX(#REF!,MATCH(BackEnd!X13,#REF!,0)+6,3)} -> #REF! | AB13: Table 12 | AC13: BL_BAU4. Where have you seen or heard any advertisement/communication about others | AD13: {=INDEX(#REF!,MATCH(BackEnd!AC13,#REF!,0)+6,3)} -> #REF! | AF13: Table 12 | AG13: EO_BAU4. Where have you seen or heard any advertisement about Golden Penny? | AH13: {=INDEX(#REF!,MATCH(BackEnd!AG13,#REF!,0)+6,3)} -> #REF! | AK13: Table 12 | AL13: SK_BAU4. And where have you seen or heard any advertisement/communication about Mr Biggs | AM13: {=INDEX(#REF!,MATCH(BackEnd!AL13,#REF!,0)+6,3)} -> #REF! | AP13: Table 12 | AQ13: CM_BAU4. And where have you seen or heard any advertisement/communication about Onga Seasoning | AR13: {=INDEX(#REF!,MATCH(BackEnd!AQ13,#REF!,0)+6,3)} -> #REF! | AU13: Table 12 | AV13: WH_BAU4. And where have you seen or heard any advertisement/communication about BEVA | AW13: {=INDEX(#REF!,MATCH(BackEnd!AV13,#REF!,0)+6,3)} -> #REF! | AZ13: Table 12 | BA13: DH_BAU4. Where have you seen or heard any advertisement about XPRESSION | BB13: {=INDEX(#REF!,MATCH(BackEnd!BA13,#REF!,0)+6,3)} -> #REF! | BE13: Table 12 | BF13: TC_BAU4. And where have you seen or heard any advertisement/communication about Mr Muscle | BG13: {=INDEX(#REF!,MATCH(BackEnd!BF13,#REF!,0)+6,3)} -> #REF!
A14: Table 9 | B14: N_BAU4. And where have you seen or heard any advertisement/communication about Golden Penny | C14: #REF! | M14: Table 13 | N14: N_BAU4. And where have you seen or heard any advertisement/communication about Minimie | O14: {=INDEX(#REF!,MATCH(BackEnd!N14,#REF!,0)+6,3)} -> #REF! | R14: Table 13 | S14: TP_BAU4. Where have you seen or heard any advertisement about Oral-B? | T14: {=INDEX(#REF!,MATCH(BackEnd!S14,#REF!,0)+6,3)} -> #REF! | W14: Table 13 | X14: BC_BAU4. Where have you seen or heard any advertisement/communication about Good Morning Cornflakes | Y14: {=INDEX(#REF!,MATCH(BackEnd!X14,#REF!,0)+6,3)} -> #REF! | AB14: Table 13 | AC14: BL_BAU5A. Which of these Bleach brands have you ever used? | AD14: {=INDEX(#REF!,MATCH(BackEnd!AC14,#REF!,0)+6,3)} -> #REF! | AF14: Table 13 | AG14: EO_BAU4. Where have you seen or heard any advertisement about Grand? | AH14: {=INDEX(#REF!,MATCH(BackEnd!AG14,#REF!,0)+6,3)} -> #REF! | AK14: Table 13 | AL14: SK_BAU4. And where have you seen or heard any advertisement/communication about Supreme | AM14: {=INDEX(#REF!,MATCH(BackEnd!AL14,#REF!,0)+6,3)} -> #REF! | AP14: Table 13 | AQ14: CM_BAU4. And where have you seen or heard any advertisement/communication about Ajinomoto | AR14: {=INDEX(#REF!,MATCH(BackEnd!AQ14,#REF!,0)+6,3)} -> #REF! | AU14: Table 13 | AV14: WH_BAU4. And where have you seen or heard any advertisement/communication about OZONE | AW14: {=INDEX(#REF!,MATCH(BackEnd!AV14,#REF!,0)+6,3)} -> #REF! | AZ14: Table 13 | BA14: DH_BAU4. Where have you seen or heard any advertisement about LADY STAR | BB14: {=INDEX(#REF!,MATCH(BackEnd!BA14,#REF!,0)+6,3)} -> #REF! | BE14: Table 13 | BF14: TC_BAU4. And where have you seen or heard any advertisement/communication about Flow Toilet Cleaner | BG14: {=INDEX(#REF!,MATCH(BackEnd!BF14,#REF!,0)+6,3)} -> #REF!
A15: Table 10 | B15: N_BAU4. And where have you seen or heard any advertisement/communication about Indomie | C15: #REF! | M15: Table 14 | N15: N_BAU4. And where have you seen or heard any advertisement/communication about Supreme | O15: {=INDEX(#REF!,MATCH(BackEnd!N15,#REF!,0)+6,3)} -> #REF! | R15: Table 14 | S15: TP_BAU4. Where have you seen or heard any advertisement about Pepsodent? | T15: {=INDEX(#REF!,MATCH(BackEnd!S15,#REF!,0)+6,3)} -> #REF! | W15: Table 14 | X15: BC_BAU4. Where have you seen or heard any advertisement/communication about Harvest Morn Cornflakes | Y15: {=INDEX(#REF!,MATCH(BackEnd!X15,#REF!,0)+6,3)} -> #REF! | AB15: Table 14 | AC15: BL_BAU5C. Which of these Bleach brands have you used in the last 3 ROLL_MONTHs? | AD15: {=INDEX(#REF!,MATCH(BackEnd!AC15,#REF!,0)+6,3)} -> #REF! | AF15: Table 14 | AG15: EO_BAU4. Where have you seen or heard any advertisement about Laziz? | AH15: {=INDEX(#REF!,MATCH(BackEnd!AG15,#REF!,0)+6,3)} -> #REF! | AK15: Table 14 | AL15: SK_BAU4. And where have you seen or heard any advertisement/communication about Fan | AM15: {=INDEX(#REF!,MATCH(BackEnd!AL15,#REF!,0)+6,3)} -> #REF! | AP15: Table 14 | AQ15: CM_BAU4. And where have you seen or heard any advertisement/communication about Doyin Seasoning | AR15: {=INDEX(#REF!,MATCH(BackEnd!AQ15,#REF!,0)+6,3)} -> #REF! | AU15: Table 14 | AV15: WH_BAU4. And where have you seen or heard any advertisement/communication about RELAX | AW15: {=INDEX(#REF!,MATCH(BackEnd!AV15,#REF!,0)+6,3)} -> #REF! | AZ15: Table 14 | BA15: DH_BAU4. Where have you seen or heard any advertisement about NAOMI | BB15: {=INDEX(#REF!,MATCH(BackEnd!BA15,#REF!,0)+6,3)} -> #REF! | BE15: Table 14 | BF15: TC_BAU4. And where have you seen or heard any advertisement/communication about Others | BG15: {=INDEX(#REF!,MATCH(BackEnd!BF15,#REF!,0)+6,3)} -> #REF!
A16: Table 11 | B16: N_BAU4. And where have you seen or heard any advertisement/communication about Mimee | C16: #REF! | M16: Table 15 | N16: N_BAU4. And where have you seen or heard any advertisement/communication about Honeywell | O16: {=INDEX(#REF!,MATCH(BackEnd!N16,#REF!,0)+6,3)} -> #REF! | R16: Table 15 | S16: TP_BAU4. Where have you seen or heard any advertisement about Sensodyne? | T16: {=INDEX(#REF!,MATCH(BackEnd!S16,#REF!,0)+6,3)} -> #REF! | W16: Table 15 | X16: BC_BAU4. Where have you seen or heard any advertisement/communication about Honey Bunches of Oats | Y16: {=INDEX(#REF!,MATCH(BackEnd!X16,#REF!,0)+6,3)} -> #REF! | AB16: Table 15 | AC16: BL_BAU6A. Which of these Bleach brands have you used in the last 1 ROLL_MONTH? | AD16: {=INDEX(#REF!,MATCH(BackEnd!AC16,#REF!,0)+6,3)} -> #REF! | AF16: Table 15 | AG16: EO_BAU4. Where have you seen or heard any advertisement about Laser? | AH16: {=INDEX(#REF!,MATCH(BackEnd!AG16,#REF!,0)+6,3)} -> #REF! | AK16: Table 15 | AL16: SK_BAU4. And where have you seen or heard any advertisement/communication about Others | AM16: {=INDEX(#REF!,MATCH(BackEnd!AL16,#REF!,0)+6,3)} -> #REF! | AP16: Table 15 | AQ16: CM_BAU4. And where have you seen or heard any advertisement/communication about Suppy Seasoning | AR16: {=INDEX(#REF!,MATCH(BackEnd!AQ16,#REF!,0)+6,3)} -> #REF! | AU16: Table 15 | AV16: WH_BAU4. And where have you seen or heard any advertisement/communication about TCB | AW16: {=INDEX(#REF!,MATCH(BackEnd!AV16,#REF!,0)+6,3)} -> #REF! | AZ16: Table 15 | BA16: DH_BAU4. Where have you seen or heard any advertisement about X-PRESTIGE | BB16: {=INDEX(#REF!,MATCH(BackEnd!BA16,#REF!,0)+6,3)} -> #REF! | BE16: Table 15 | BF16: TC_BAU5A. Which of these Toilet cleaner brands have you ever used | BG16: {=INDEX(#REF!,MATCH(BackEnd!BF16,#REF!,0)+6,3)} -> #REF!
A17: Table 12 | B17: N_BAU4. And where have you seen or heard any advertisement/communication about Tummy Tummy | C17: #REF! | M17: Table 16 | N17: N_BAU4. And where have you seen or heard any advertisement/communication about Tasty Tom | O17: {=INDEX(#REF!,MATCH(BackEnd!N17,#REF!,0)+6,3)} -> #REF! | R17: Table 16 | S17: TP_BAU4. Where have you seen or heard any advertisement about Olive? | T17: {=INDEX(#REF!,MATCH(BackEnd!S17,#REF!,0)+6,3)} -> #REF! | W17: Table 16 | X17: BC_BAU4. Where have you seen or heard any advertisement/communication about Infinity Cornflakes | Y17: {=INDEX(#REF!,MATCH(BackEnd!X17,#REF!,0)+6,3)} -> #REF! | AB17: Table 16 | AC17: BL_BAU6B. Which of these Bleach brands have you used in the last 7 days? | AD17: {=INDEX(#REF!,MATCH(BackEnd!AC17,#REF!,0)+6,3)} -> #REF! | AF17: Table 16 | AG17: EO_BAU4. Where have you seen or heard any advertisement about Devon King’s? | AH17: {=INDEX(#REF!,MATCH(BackEnd!AG17,#REF!,0)+6,3)} -> #REF! | AK17: Table 16 | AL17: SK_BAU5A. Which of these Snack brands have you ever consumed | AM17: {=INDEX(#REF!,MATCH(BackEnd!AL17,#REF!,0)+6,3)} -> #REF! | AP17: Table 16 | AQ17: CM_BAU4 And where have you seen or heard any advertisement/communication about Gino Curry Powder | AR17: {=INDEX(#REF!,MATCH(BackEnd!AQ17,#REF!,0)+6,3)} -> #REF! | AU17: Table 16 | AV17: WH_BAU4. And where have you seen or heard any advertisement/communication about EBONY | AW17: {=INDEX(#REF!,MATCH(BackEnd!AV17,#REF!,0)+6,3)} -> #REF! | AZ17: Table 16 | BA17: DH_BAU4. Where have you seen or heard any advertisement about AVIV | BB17: {=INDEX(#REF!,MATCH(BackEnd!BA17,#REF!,0)+6,3)} -> #REF! | BE17: Table 16 | BF17: TC_BAU5C. And which of these Toilet cleaner brands have you used in the last 3 ROLL_MONTHs | BG17: {=INDEX(#REF!,MATCH(BackEnd!BF17,#REF!,0)+6,3)} -> #REF!
A18: Table 13 | B18: N_BAU4. And where have you seen or heard any advertisement/communication about Minimie | C18: #REF! | M18: Table 17 | N18: N_BAU4. And where have you seen or heard any advertisement/communication about Jolly Jolly | O18: {=INDEX(#REF!,MATCH(BackEnd!N18,#REF!,0)+6,3)} -> #REF! | R18: Table 17 | S18: TP_BAU4. Where have you seen or heard any advertisement about Oracare +? | T18: {=INDEX(#REF!,MATCH(BackEnd!S18,#REF!,0)+6,3)} -> #REF! | W18: Table 17 | X18: BC_BAU4. Where have you seen or heard any advertisement/communication about Kellogg’s Coco Pops | Y18: {=INDEX(#REF!,MATCH(BackEnd!X18,#REF!,0)+6,3)} -> #REF! | AB18: Table 17 | AC18: BL_BAU6C. Which one brand of Bleach do you consume most often and would call your main brand? | AD18: {=INDEX(#REF!,MATCH(BackEnd!AC18,#REF!,0)+6,3)} -> #REF! | AF18: Table 17 | AG18: EO_BAU4. Where have you seen or heard any advertisement about Sunola? | AH18: {=INDEX(#REF!,MATCH(BackEnd!AG18,#REF!,0)+6,3)} -> #REF! | AK18: Table 17 | AL18: SK_BAU5C. And which of these Snack brands have you consumed in the last 3 ROLL_MONTH? | AM18: {=INDEX(#REF!,MATCH(BackEnd!AL18,#REF!,0)+6,3)} -> #REF! | AP18: Table 17 | AQ18: CM_BAU4 And where have you seen or heard any advertisement/communication about Benny Chicken Seasoning | AR18: {=INDEX(#REF!,MATCH(BackEnd!AQ18,#REF!,0)+6,3)} -> #REF! | AU18: Table 17 | AV18: WH_BAU4. And where have you seen or heard any advertisement/communication about LUSH | AW18: {=INDEX(#REF!,MATCH(BackEnd!AV18,#REF!,0)+6,3)} -> #REF! | AZ18: Table 17 | BA18: DH_BAU4. Where have you seen or heard any advertisement about HairSense | BB18: {=INDEX(#REF!,MATCH(BackEnd!BA18,#REF!,0)+6,3)} -> #REF! | BE18: Table 17 | BF18: TC_BAU6A. And which of these Toilet cleaner brands have you used in the last 1 ROLL_MONTH | BG18: {=INDEX(#REF!,MATCH(BackEnd!BF18,#REF!,0)+6,3)} -> #REF!
A19: Table 14 | B19: N_BAU4. And where have you seen or heard any advertisement/communication about Supreme | C19: #REF! | M19: Table 18 | N19: N_BAU4. And where have you seen or heard any advertisement/communication about Masters | O19: {=INDEX(#REF!,MATCH(BackEnd!N19,#REF!,0)+6,3)} -> #REF! | R19: Table 18 | S19: TP_BAU4. Where have you seen or heard any advertisement about Xtreme? | T19: {=INDEX(#REF!,MATCH(BackEnd!S19,#REF!,0)+6,3)} -> #REF! | W19: Table 18 | X19: BC_BAU4. Where have you seen or heard any advertisement/communication about Kellogg’s Cornflakes | Y19: {=INDEX(#REF!,MATCH(BackEnd!X19,#REF!,0)+6,3)} -> #REF! | AB19: Table 18 | AC19: BL_BAU6D. Please tell me the primary reason for consuming the brand | AD19: {=INDEX(#REF!,MATCH(BackEnd!AC19,#REF!,0)+6,3)} -> #REF! | AF19: Table 18 | AG19: EO_BAU4. Where have you seen or heard any advertisement about Wesson? | AH19: {=INDEX(#REF!,MATCH(BackEnd!AG19,#REF!,0)+6,3)} -> #REF! | AK19: Table 18 | AL19: SK_BAU6A. And which of these Snack brands have you consumed in the last 1 ROLL_MONTH | AM19: {=INDEX(#REF!,MATCH(BackEnd!AL19,#REF!,0)+6,3)} -> #REF! | AP19: Table 18 | AQ19: CM_BAU4 And where have you seen or heard any advertisement/communication about Others | AR19: {=INDEX(#REF!,MATCH(BackEnd!AQ19,#REF!,0)+6,3)} -> #REF! | AU19: Table 18 | AV19: WH_BAU4. And where have you seen or heard any advertisement/communication about TOPKLASS | AW19: {=INDEX(#REF!,MATCH(BackEnd!AV19,#REF!,0)+6,3)} -> #REF! | AZ19: Table 18 | BA19: DH_BAU4. And where have you seen or heard any advertisement/communication about Others | BB19: {=INDEX(#REF!,MATCH(BackEnd!BA19,#REF!,0)+6,3)} -> #REF! | BE19: Table 18 | BF19: TC_BAU6B. And which of these Toilet cleaner brands have you used in the last 7 days | BG19: {=INDEX(#REF!,MATCH(BackEnd!BF19,#REF!,0)+6,3)} -> #REF!
A20: Table 15 | B20: N_BAU4. And where have you seen or heard any advertisement/communication about Honeywell | C20: #REF! | M20: Table 19 | N20: N_BAU4. And where have you seen or heard any advertisement/communication about Bestie | O20: {=INDEX(#REF!,MATCH(BackEnd!N20,#REF!,0)+6,3)} -> #REF! | R20: Table 19 | S20: TP_BAU4. Where have you seen or heard any advertisement about Others? | T20: {=INDEX(#REF!,MATCH(BackEnd!S20,#REF!,0)+6,3)} -> #REF! | W20: Table 19 | X20: BC_BAU4. Where have you seen or heard any advertisement/communication about Kellogg’s Rice Krispies | Y20: {=INDEX(#REF!,MATCH(BackEnd!X20,#REF!,0)+6,3)} -> #REF! | AB20: Table 19 | AC20: BL_BAU8. Which of these brands of Bleach do you prefer the most? | AD20: {=INDEX(#REF!,MATCH(BackEnd!AC20,#REF!,0)+6,3)} -> #REF! | AF20: Table 19 | AG20: EO_BAU4. Where have you seen or heard any advertisement about Activa? | AH20: {=INDEX(#REF!,MATCH(BackEnd!AG20,#REF!,0)+6,3)} -> #REF! | AK20: Table 19 | AL20: SK_BAU6B. And which of these Snack brands have you consumed in the last 7 days | AM20: {=INDEX(#REF!,MATCH(BackEnd!AL20,#REF!,0)+6,3)} -> #REF! | AP20: Table 19 | AQ20: CM_BAU5A. Which of these Condiment mix brands have you ever used | AR20: {=INDEX(#REF!,MATCH(BackEnd!AQ20,#REF!,0)+6,3)} -> #REF! | AU20: Table 19 | AV20: WH_BAU4. And where have you seen or heard any advertisement/communication about PETALS | AW20: {=INDEX(#REF!,MATCH(BackEnd!AV20,#REF!,0)+6,3)} -> #REF! | AZ20: Table 19 | BA20: DH_BAU5A. Which of these Hair Extension brands have you ever used | BB20: {=INDEX(#REF!,MATCH(BackEnd!BA20,#REF!,0)+6,3)} -> #REF! | BE20: Table 19 | BF20: TC_BAU6C. Which one brand of Toilet cleaner do you consume most often and would call as your main brand? | BG20: {=INDEX(#REF!,MATCH(BackEnd!BF20,#REF!,0)+0,3)} -> #REF!
A21: Table 16 | B21: N_BAU4. And where have you seen or heard any advertisement/communication about Tasty Tom | C21: #REF! | M21: Table 20 | N21: N_BAU4. And where have you seen or heard any advertisement/communication about Others | O21: {=INDEX(#REF!,MATCH(BackEnd!N21,#REF!,0)+6,3)} -> #REF! | R21: Table 20 | S21: TP_BAU5A. Which of these Toothpaste brands have you ever used? | T21: {=INDEX(#REF!,MATCH(BackEnd!S21,#REF!,0)+6,3)} -> #REF! | W21: Table 20 | X21: BC_BAU4. Where have you seen or heard any advertisement/communication about Luna Cereal | Y21: {=INDEX(#REF!,MATCH(BackEnd!X21,#REF!,0)+6,3)} -> #REF! | AB21: Table 20 | AC21: BL_BAU9. How often do you purchase bleach? | AD21: {=INDEX(#REF!,MATCH(BackEnd!AC21,#REF!,0)+6,3)} -> #REF! | AF21: Table 20 | AG21: EO_BAU4. Where have you seen or heard any advertisement about Casa de Campo? | AH21: {=INDEX(#REF!,MATCH(BackEnd!AG21,#REF!,0)+6,3)} -> #REF! | AK21: Table 20 | AL21: SK_BAU6C. Which one brand of Snack do you consume most often and would call as your main brand? | AM21: {=INDEX(#REF!,MATCH(BackEnd!AL21,#REF!,0)+0,3)} -> #REF! | AP21: Table 20 | AQ21: CM_BAU5C. And which of these Condiment mix brands have you used in the last 3 ROLL_MONTHs | AR21: {=INDEX(#REF!,MATCH(BackEnd!AQ21,#REF!,0)+6,3)} -> #REF! | AU21: Table 20 | AV21: WH_BAU4. And where have you seen or heard any advertisement/communication about PROFECTIV MEGA GROWTH | AW21: {=INDEX(#REF!,MATCH(BackEnd!AV21,#REF!,0)+6,3)} -> #REF! | AZ21: Table 20 | BA21: DH_BAU5C. Which of these Hair Extension brands have you used in the last 3 ROLL_MONTH? | BB21: {=INDEX(#REF!,MATCH(BackEnd!BA21,#REF!,0)+6,3)} -> #REF! | BE21: Table 20 | BF21: TC_BAU6D. Please tell me the primary reason for consuming the Brand | BG21: {=INDEX(#REF!,MATCH(BackEnd!BF21,#REF!,0)+6,3)} -> #REF!
A22: Table 17 | B22: N_BAU4. And where have you seen or heard any advertisement/communication about Jolly Jolly | C22: #REF! | M22: Table 21 | N22: N_BAU5A. Which of these instant Noodles brands have you ever consumed? | O22: {=INDEX(#REF!,MATCH(BackEnd!N22,#REF!,0)+6,3)} -> #REF! | R22: Table 21 | S22: TP_BAU5C. Which of these Toothpaste brands have you ever used in the last 3 ROLL_MONTHs? | T22: {=INDEX(#REF!,MATCH(BackEnd!S22,#REF!,0)+6,3)} -> #REF! | W22: Table 21 | X22: BC_BAU4. Where have you seen or heard any advertisement/communication about NASCO Cornflakes | Y22: {=INDEX(#REF!,MATCH(BackEnd!X22,#REF!,0)+6,3)} -> #REF! | AB22: Table 21 | AC22: BL_BAU10. What pack size of bleach do you buy most often? | AD22: {=INDEX(#REF!,MATCH(BackEnd!AC22,#REF!,0)+6,3)} -> #REF! | AF22: Table 21 | AG22: EO_BAU4. Where have you seen or heard any advertisement about Unbranded/Loose Oil? | AH22: {=INDEX(#REF!,MATCH(BackEnd!AG22,#REF!,0)+6,3)} -> #REF! | AK22: Table 21 | AL22: SK_BAU6D. Please tell me the primary reason for consuming the Brand | AM22: {=INDEX(#REF!,MATCH(BackEnd!AL22,#REF!,0)+6,3)} -> #REF! | AP22: Table 21 | AQ22: CM_BAU6A. And which of these Condiment mix brands have you used in the last 1 ROLL_MONTH | AR22: {=INDEX(#REF!,MATCH(BackEnd!AQ22,#REF!,0)+6,3)} -> #REF! | AU22: Table 21 | AV22: WH_BAU4. And where have you seen or heard any advertisement/communication about HAIR WONDER | AW22: {=INDEX(#REF!,MATCH(BackEnd!AV22,#REF!,0)+6,3)} -> #REF! | AZ22: Table 21 | BA22: DH_BAU6A. Which of these Hair Extension brands have you used in the last 1 ROLL_MONTH | BB22: {=INDEX(#REF!,MATCH(BackEnd!BA22,#REF!,0)+6,3)} -> #REF! | BE22: Table 21 | BF22: TC_BAU8. Which of these brands of Toilet cleaner do you prefer the most? | BG22: {=INDEX(#REF!,MATCH(BackEnd!BF22,#REF!,0)+0,3)} -> #REF!
